2019-02-18 23:48:18 jdbc[3]: exception
org.h2.jdbc.JdbcSQLException: Column "Carlos Sedano" not found; SQL statement:
insert into persons values("Carlos Sedano") [42122-197]
	at org.h2.message.DbException.getJdbcSQLException(DbException.java:357)
	at org.h2.message.DbException.get(DbException.java:179)
	at org.h2.message.DbException.get(DbException.java:155)
	at org.h2.expression.ExpressionColumn.optimize(ExpressionColumn.java:150)
	at org.h2.command.dml.Insert.prepare(Insert.java:314)
	at org.h2.command.Parser.prepareCommand(Parser.java:283)
	at org.h2.engine.Session.prepareLocal(Session.java:611)
	at org.h2.engine.Session.prepareCommand(Session.java:549)
	at org.h2.jdbc.JdbcConnection.prepareCommand(JdbcConnection.java:1247)
	at org.h2.jdbc.JdbcStatement.executeInternal(JdbcStatement.java:217)
	at org.h2.jdbc.JdbcStatement.execute(JdbcStatement.java:1077)
	at org.h2.server.web.WebApp.getResult(WebApp.java:1386)
	at org.h2.server.web.WebApp.query(WebApp.java:1060)
	at org.h2.server.web.WebApp$1.next(WebApp.java:1022)
	at org.h2.server.web.WebApp$1.next(WebApp.java:1009)
	at org.h2.server.web.WebThread.process(WebThread.java:165)
	at org.h2.server.web.WebThread.run(WebThread.java:90)
	at java.lang.Thread.run(Unknown Source)
2019-02-18 23:48:44 jdbc[3]: exception
org.h2.jdbc.JdbcSQLException: Column "Carlos Sedano" not found; SQL statement:
insert into PERSONS values("Carlos Sedano") [42122-197]
	at org.h2.message.DbException.getJdbcSQLException(DbException.java:357)
	at org.h2.message.DbException.get(DbException.java:179)
	at org.h2.message.DbException.get(DbException.java:155)
	at org.h2.expression.ExpressionColumn.optimize(ExpressionColumn.java:150)
	at org.h2.command.dml.Insert.prepare(Insert.java:314)
	at org.h2.command.Parser.prepareCommand(Parser.java:283)
	at org.h2.engine.Session.prepareLocal(Session.java:611)
	at org.h2.engine.Session.prepareCommand(Session.java:549)
	at org.h2.jdbc.JdbcConnection.prepareCommand(JdbcConnection.java:1247)
	at org.h2.jdbc.JdbcStatement.executeInternal(JdbcStatement.java:217)
	at org.h2.jdbc.JdbcStatement.execute(JdbcStatement.java:1077)
	at org.h2.server.web.WebApp.getResult(WebApp.java:1386)
	at org.h2.server.web.WebApp.query(WebApp.java:1060)
	at org.h2.server.web.WebApp$1.next(WebApp.java:1022)
	at org.h2.server.web.WebApp$1.next(WebApp.java:1009)
	at org.h2.server.web.WebThread.process(WebThread.java:165)
	at org.h2.server.web.WebThread.run(WebThread.java:90)
	at java.lang.Thread.run(Unknown Source)
2019-02-18 23:48:55 jdbc[3]: exception
org.h2.jdbc.JdbcSQLException: Syntax error in SQL statement "INSERT INTO PERSONS VALUE[*](""Carlos Sedano"") "; expected "., (, DIRECT, SORTED, DEFAULT, VALUES, SET, (, WITH, SELECT, FROM"; SQL statement:
insert into PERSONS value("Carlos Sedano") [42001-197]
2019-02-18 23:49:08 jdbc[3]: exception
org.h2.jdbc.JdbcSQLException: Column "Carlos Sedano" not found; SQL statement:
INSERT INTO PERSONS VALUES("Carlos Sedano") [42122-197]
	at org.h2.message.DbException.getJdbcSQLException(DbException.java:357)
	at org.h2.message.DbException.get(DbException.java:179)
	at org.h2.message.DbException.get(DbException.java:155)
	at org.h2.expression.ExpressionColumn.optimize(ExpressionColumn.java:150)
	at org.h2.command.dml.Insert.prepare(Insert.java:314)
	at org.h2.command.Parser.prepareCommand(Parser.java:283)
	at org.h2.engine.Session.prepareLocal(Session.java:611)
	at org.h2.engine.Session.prepareCommand(Session.java:549)
	at org.h2.jdbc.JdbcConnection.prepareCommand(JdbcConnection.java:1247)
	at org.h2.jdbc.JdbcStatement.executeInternal(JdbcStatement.java:217)
	at org.h2.jdbc.JdbcStatement.execute(JdbcStatement.java:1077)
	at org.h2.server.web.WebApp.getResult(WebApp.java:1386)
	at org.h2.server.web.WebApp.query(WebApp.java:1060)
	at org.h2.server.web.WebApp$1.next(WebApp.java:1022)
	at org.h2.server.web.WebApp$1.next(WebApp.java:1009)
	at org.h2.server.web.WebThread.process(WebThread.java:165)
	at org.h2.server.web.WebThread.run(WebThread.java:90)
	at java.lang.Thread.run(Unknown Source)
2019-02-19 00:01:36 database: wrong user or password; user: ""
org.h2.message.DbException: Wrong user name or password [28000-197]
	at org.h2.message.DbException.get(DbException.java:179)
	at org.h2.message.DbException.get(DbException.java:155)
	at org.h2.message.DbException.get(DbException.java:144)
	at org.h2.engine.Engine.openSession(Engine.java:107)
	at org.h2.engine.Engine.openSession(Engine.java:179)
	at org.h2.engine.Engine.createSessionAndValidate(Engine.java:157)
	at org.h2.engine.Engine.createSession(Engine.java:140)
	at org.h2.engine.Engine.createSession(Engine.java:28)
	at org.h2.engine.SessionRemote.connectEmbeddedOrServer(SessionRemote.java:351)
	at org.h2.jdbc.JdbcConnection.<init>(JdbcConnection.java:124)
	at org.h2.jdbc.JdbcConnection.<init>(JdbcConnection.java:103)
	at org.h2.Driver.connect(Driver.java:69)
	at java.sql.DriverManager.getConnection(DriverManager.java:664)
	at java.sql.DriverManager.getConnection(DriverManager.java:270)
	at h2Connection.connect(h2Connection.java:10)
	at h2Connection.consultar(h2Connection.java:20)
	at h2Connection.main(h2Connection.java:40)
Caused by: org.h2.jdbc.JdbcSQLException: Wrong user name or password [28000-197]
	at org.h2.message.DbException.getJdbcSQLException(DbException.java:357)
	... 17 more
2019-02-19 00:02:11 jdbc[3]: exception
org.h2.jdbc.JdbcSQLException: The object is already closed [90007-197]
2019-02-19 00:03:41 jdbc[3]: exception
org.h2.jdbc.JdbcSQLException: The object is already closed [90007-197]
